2025-03-31 14:51:41,829 - sentence_transformers.SentenceTransformer - INFO - Use pytorch device_name: cuda
2025-03-31 14:51:41,830 - sentence_transformers.SentenceTransformer - INFO - Load pretrained SentenceTransformer: sentence-transformers/all-mpnet-base-v2
2025-03-31 14:52:11,590 - api.langchain_utils - INFO - No existing FAISS index found. Index will be created on update.
2025-03-31 14:52:11,593 - api.main - INFO - Running startup event...
2025-03-31 14:52:12,507 - rss_feed_ingestor - INFO - Fetched 26 articles from BBC News
2025-03-31 14:52:12,507 - api.main - INFO - Successfully ingested 5 from BBC"
2025-03-31 14:52:15,039 - rss_feed_ingestor - INFO - Fetched 26 articles from NYT > Technology
2025-03-31 14:52:15,039 - api.main - INFO - Successfully ingested 5 from NYTimes"
2025-03-31 14:52:15,330 - faiss.loader - INFO - Loading faiss with AVX2 support.
2025-03-31 14:52:15,386 - faiss.loader - INFO - Successfully loaded faiss with AVX2 support.
2025-03-31 14:52:15,391 - faiss - INFO - Failed to load GPU Faiss: name 'GpuIndexIVFFlat' is not defined. Will not load constructor refs for GPU indexes.
2025-03-31 14:52:15,399 - api.langchain_utils - INFO - Updated FAISS index saved to data/rag_data/realtime_data_index
2025-03-31 14:52:15,399 - api.main - ERROR - Error updating RAG index after ingestion: object NoneType can't be used in 'await' expression
2025-03-31 14:52:15,399 - api.main - INFO - Startup event completed.
2025-03-31 14:54:57,152 - api.langchain_utils - INFO - Retrieved context: ['title 5 us voters weigh in on the signal leak\nsummary what did they think about the national security breach in which trump administration officials discussed attack plans in yemen on a commercial messaging app\nlink httpswwwnytimescom20250329ustrumpsignalleakwarplanshtml', 'title fcc orders investigation into disneys dei practices\nsummary the chairman brendan carr sent a letter to the company accusing it of violating equal employment opportunity regulations\nlink httpswwwnytimescom20250328technologydisneyfccdeiinvestigationhtml', 'title they met for 30 seconds  she then stalked him for four years\nsummary victims tell bbc panorama how a prolific stalker posted thousands of abusive messages about them on social media\nlink httpswwwbbccomnewsarticlesc5y9134jy0jo', 'title coreweave disappoints on opening of trading\nsummary the startup which provides the processing power to help develop ai systems faces questions about its debt and the overall economy\nlink httpswwwnytimescom20250328technologycoreweavestockhtml', 'title germany decides to leave history in the past and prepare for war\nsummary russian aggression and us isolationism push a once hesitant germany to invest heavily in defence\nlink httpswwwbbccomnewsarticlescdjyjlkewr2o']
2025-03-31 14:54:57,829 - api.main - INFO - Detected input type: misinfo for query: Did the Illuminati create the internet?...
2025-03-31 14:54:58,116 - api.factcheck_api_util - ERROR - Fact Check API request failed: HTTPSConnectionPool(host='factcheckapi.org', port=443): Max retries exceeded with url: /check (Caused by NameResolutionError("<urllib3.connection.HTTPSConnection object at 0x73f63e1616d0>: Failed to resolve 'factcheckapi.org' ([Errno -2] Name or service not known)"))
Traceback (most recent call last):
  File "/home/cykosynergy/falo/env/lib/python3.13/site-packages/urllib3/connection.py", line 198, in _new_conn
    sock = connection.create_connection(
        (self._dns_host, self.port),
    ...<2 lines>...
        socket_options=self.socket_options,
    )
  File "/home/cykosynergy/falo/env/lib/python3.13/site-packages/urllib3/util/connection.py", line 60, in create_connection
    for res in socket.getaddrinfo(host, port, family, socket.SOCK_STREAM):
               ~~~~~~~~~~~~~~~~~~^^^^^^^^^^^^^^^^^^^^^^^^^^^^^^^^^^^^^^^^
  File "/usr/lib/python3.13/socket.py", line 977, in getaddrinfo
    for res in _socket.getaddrinfo(host, port, family, type, proto, flags):
               ~~~~~~~~~~~~~~~~~~~^^^^^^^^^^^^^^^^^^^^^^^^^^^^^^^^^^^^^^^^
socket.gaierror: [Errno -2] Name or service not known

The above exception was the direct cause of the following exception:

Traceback (most recent call last):
  File "/home/cykosynergy/falo/env/lib/python3.13/site-packages/urllib3/connectionpool.py", line 787, in urlopen
    response = self._make_request(
        conn,
    ...<10 lines>...
        **response_kw,
    )
  File "/home/cykosynergy/falo/env/lib/python3.13/site-packages/urllib3/connectionpool.py", line 488, in _make_request
    raise new_e
  File "/home/cykosynergy/falo/env/lib/python3.13/site-packages/urllib3/connectionpool.py", line 464, in _make_request
    self._validate_conn(conn)
    ~~~~~~~~~~~~~~~~~~~^^^^^^
  File "/home/cykosynergy/falo/env/lib/python3.13/site-packages/urllib3/connectionpool.py", line 1093, in _validate_conn
    conn.connect()
    ~~~~~~~~~~~~^^
  File "/home/cykosynergy/falo/env/lib/python3.13/site-packages/urllib3/connection.py", line 704, in connect
    self.sock = sock = self._new_conn()
                       ~~~~~~~~~~~~~~^^
  File "/home/cykosynergy/falo/env/lib/python3.13/site-packages/urllib3/connection.py", line 205, in _new_conn
    raise NameResolutionError(self.host, self, e) from e
urllib3.exceptions.NameResolutionError: <urllib3.connection.HTTPSConnection object at 0x73f63e1616d0>: Failed to resolve 'factcheckapi.org' ([Errno -2] Name or service not known)

The above exception was the direct cause of the following exception:

Traceback (most recent call last):
  File "/home/cykosynergy/falo/env/lib/python3.13/site-packages/requests/adapters.py", line 486, in send
    resp = conn.urlopen(
        method=request.method,
    ...<9 lines>...
        chunked=chunked,
    )
  File "/home/cykosynergy/falo/env/lib/python3.13/site-packages/urllib3/connectionpool.py", line 841, in urlopen
    retries = retries.increment(
        method, url, error=new_e, _pool=self, _stacktrace=sys.exc_info()[2]
    )
  File "/home/cykosynergy/falo/env/lib/python3.13/site-packages/urllib3/util/retry.py", line 519, in increment
    raise MaxRetryError(_pool, url, reason) from reason  # type: ignore[arg-type]
    ^^^^^^^^^^^^^^^^^^^^^^^^^^^^^^^^^^^^^^^^^^^^^^^^^^^
urllib3.exceptions.MaxRetryError: HTTPSConnectionPool(host='factcheckapi.org', port=443): Max retries exceeded with url: /check (Caused by NameResolutionError("<urllib3.connection.HTTPSConnection object at 0x73f63e1616d0>: Failed to resolve 'factcheckapi.org' ([Errno -2] Name or service not known)"))

During handling of the above exception, another exception occurred:

Traceback (most recent call last):
  File "/home/cykosynergy/falo/misinformation_detection/api/factcheck_api_util.py", line 16, in query_fact_check_api
    response = requests.post(url, headers=headers, data=payload)
  File "/home/cykosynergy/falo/env/lib/python3.13/site-packages/requests/api.py", line 115, in post
    return request("post", url, data=data, json=json, **kwargs)
  File "/home/cykosynergy/falo/env/lib/python3.13/site-packages/requests/api.py", line 59, in request
    return session.request(method=method, url=url, **kwargs)
           ~~~~~~~~~~~~~~~^^^^^^^^^^^^^^^^^^^^^^^^^^^^^^^^^^
  File "/home/cykosynergy/falo/env/lib/python3.13/site-packages/requests/sessions.py", line 589, in request
    resp = self.send(prep, **send_kwargs)
  File "/home/cykosynergy/falo/env/lib/python3.13/site-packages/requests/sessions.py", line 703, in send
    r = adapter.send(request, **kwargs)
  File "/home/cykosynergy/falo/env/lib/python3.13/site-packages/requests/adapters.py", line 519, in send
    raise ConnectionError(e, request=request)
requests.exceptions.ConnectionError: HTTPSConnectionPool(host='factcheckapi.org', port=443): Max retries exceeded with url: /check (Caused by NameResolutionError("<urllib3.connection.HTTPSConnection object at 0x73f63e1616d0>: Failed to resolve 'factcheckapi.org' ([Errno -2] Name or service not known)"))
2025-03-31 14:54:59,398 - api.groq_utils - INFO - Misinformation analysis complete. Category: hoax
